Workbook

Sheet Ekspor Ringkasan
B3: Dokumen ini diekspor dari Numbers. Setiap tabel dikonversi ke lembar kerja Excel. Semua objek lainnya pada setiap lembar Numbers ditempatkan pada lembar kerja terpisah. Harap diperhatikan bahwa kalkulasi formula itu mungkin berbeda di Excel.
B7: Nama Lembar Numbers | C7: Nama Tabel Numbers | D7: Nama Lembar Kerja Excel
B9: 49013066
C10: Tabel 1 | D10: 49013066
B11: 49013206
C12: Tabel 1 | D12: 49013206
B13: 49013151
C14: Tabel 1 | D14: 49013151
B15: 49013260
C16: Tabel 1 | D16: 49013260
B17: 49015188
C18: Tabel 1 | D18: 49015188
B19: 49015289
C20: Tabel 1 | D20: 49015289
B21: 49013313
C22: Tabel 1 | D22: 49013313
B23: 49013354
C24: Tabel 1 | D24: 49013354
B25: 49013411
C26: Tabel 1 | D26: 49013411
B27: 49013538
C28: Tabel 1 | D28: 49013538
B29: 49978186
C30: Tabel 1 | D30: 49978186
B31: 49978825 /
C32: Tabel 1 | D32: 49978825 _
B33: 49976430
C34: Tabel 1 | D34: 49976430
B35: 49976716
C36: Tabel 1 | D36: 49976716
B37: 49975362
C38: Tabel 1 | D38: 49975362
B39: 49974911
C40: Tabel 1 | D40: 49974911
B41: 49978186-1
C42: Tabel 1 | D42: 49978186-1
B43: 51309562
C44: Tabel 1 | D44: 51309562
B45: 49014437
C46: Tabel 1 | D46: 49014437
...

Sheet 49013066
A1: No. | B1: Uraian Pekerjaan | D1: Kuantitas | G1: Satuan | H1: Harga Satuan | K1: PAJAK | L1: JUMLAH
D2: HPS | E2: Penawaran | F2: Negoisasi | H2: HPS | I2: Penawaran | J2: Negoisasi | L2: HPS | M2: Penawaran | N2: Negoisasi
B3: DIVISI 1. UMUM | L3: {=IF(D3>0,IF($D3<=0,0,D3*H3),"")} | M3: {=IF(E3>0,IF($D3<=0,0,ROUND(E3*I3,2)),"")} | N3: {=IF(F3>0,IF($D3<=0,0,ROUND(F3*J3,2)),"")}
A4: 1.2 | B4: Mobilisasi | D4: 1 | E4: {=D4} -> 1 | F4: {=D4} -> 1 | G4: LS | H4: 12793750 | I4: 12770750 | J4: 12770750 | K4: 11 | L4: {=IF(D4>0,IF($D4<=0,0,D4*H4),"")} -> 12793750 | M4: {=IF(E4>0,IF($D4<=0,0,ROUND(E4*I4,2)),"")} -> 12770750 | N4: {=IF(F4>0,IF($D4<=0,0,ROUND(F4*J4,2)),"")} -> 12770750
A5: 1.8.(1) | B5: Manajemen dan Keselamatan Lalu Lintas | D5: 1 | E5: {=D5} -> 1 | F5: {=D5} -> 1 | G5: LS | H5: 660000 | I5: 638000 | J5: 638000 | K5: 11 | L5: {=IF(D5>0,IF($D5<=0,0,D5*H5),"")} -> 660000 | M5: {=IF(E5>0,IF($D5<=0,0,ROUND(E5*I5,2)),"")} -> 638000 | N5: {=IF(F5>0,IF($D5<=0,0,ROUND(F5*J5,2)),"")} -> 638000
A6: 1.19 | B6: Keselamatan dan Kesehatan Kerja | D6: 1 | E6: {=D6} -> 1 | F6: {=D6} -> 1 | G6: LS | H6: 5289000 | I6: 5279000 | J6: 5279000 | K6: 11 | L6: {=IF(D6>0,IF($D6<=0,0,D6*H6),"")} -> 5289000 | M6: {=IF(E6>0,IF($D6<=0,0,ROUND(E6*I6,2)),"")} -> 5279000 | N6: {=IF(F6>0,IF($D6<=0,0,ROUND(F6*J6,2)),"")} -> 5279000
B7: DIVISI 2. DRAINASE | L7: {=IF(D7>0,IF($D7<=0,0,D7*H7),"")} | M7: {=IF(E7>0,IF($D7<=0,0,ROUND(E7*I7,2)),"")} | N7: {=IF(F7>0,IF($D7<=0,0,ROUND(F7*J7,2)),"")}
A8: 2.1.(1) | B8: Galian untuk Selokan Drainase dan Saluran Air | D8: 118.8 | E8: {=D8} -> 118.8 | F8: {=D8} -> 118.8 | G8: M3 | H8: 35065.04 | I8: 35018.61 | J8: 35018.61 | K8: 11 | L8: {=IF(D8>0,IF($D8<=0,0,D8*H8),"")} -> 4165726.8 | M8: {=IF(E8>0,IF($D8<=0,0,ROUND(E8*I8,2)),"")} -> 4160210.9 | N8: {=IF(F8>0,IF($D8<=0,0,ROUND(F8*J8,2)),"")} -> 4160210.9
B9: DIVISI 3. PEKERJAAN TANAH DAN GEOSINTETIK | L9: {=IF(D9>0,IF($D9<=0,0,D9*H9),"")} | M9: {=IF(E9>0,IF($D9<=0,0,ROUND(E9*I9,2)),"")} | N9: {=IF(F9>0,IF($D9<=0,0,ROUND(F9*J9,2)),"")}
A10: 3.1.(1) | B10: Galian Biasa (Cuttingan) | D10: 2185 | E10: {=D10} -> 2185 | F10: {=D10} -> 2185 | G10: M3 | H10: 44543.07 | I10: 44495.18 | J10: 44495.18 | K10: 11 | L10: {=IF(D10>0,IF($D10<=0,0,D10*H10),"")} -> 97326608 | M10: {=IF(E10>0,IF($D10<=0,0,ROUND(E10*I10,2)),"")} -> 97221968 | N10: {=IF(F10>0,IF($D10<=0,0,ROUND(F10*J10,2)),"")} -> 97221968
A11: 3.2.(1b) | B11: Timbunan Pilihan dari Sumber galian | D11: 310.5 | E11: {=D11} -> 310.5 | F11: {=D11} -> 310.5 | G11: M3 | H11: 156986.36 | I11: 156981.81 | J11: 156981.81 | K11: 11 | L11: {=IF(D11>0,IF($D11<=0,0,D11*H11),"")} -> 48744265 | M11: {=IF(E11>0,IF($D11<=0,0,ROUND(E11*I11,2)),"")} -> 48742852 | N11: {=IF(F11>0,IF($D11<=0,0,ROUND(F11*J11,2)),"")} -> 48742852
A12: 3.3.(1) | B12: Penyiapan Badan Jalan | D12: 2115 | E12: {=D12} -> 2115 | F12: {=D12} -> 2115 | G12: M2 | H12: 2996.59 | I12: 2994.89 | J12: 2994.89 | K12: 11 | L12: {=IF(D12>0,IF($D12<=0,0,D12*H12),"")} -> 6337787.8 | M12: {=IF(E12>0,IF($D12<=0,0,ROUND(E12*I12,2)),"")} -> 6334192.3 | N12: {=IF(F12>0,IF($D12<=0,0,ROUND(F12*J12,2)),"")} -> 6334192.3
B13: Biaya BPJS Ketenaga Kerjaan | L13: {=IF(D13>0,IF($D13<=0,0,D13*H13),"")}
A14: 1 | B14: JKK/JKM | D14: 1 | E14: {=D14} -> 1 | F14: {=D14} -> 1 | G14: LS | H14: 383102.54 | I14: 382779.25 | J14: 382779.25 | K14: 0 | L14: {=IF(D14>0,IF($D14<=0,0,D14*H14),"")} -> 383102.54 | M14: {=IF(E14>0,IF($D14<=0,0,ROUND(E14*I14,2)),"")} -> 382779.25 | N14: {=IF(F14>0,IF($D14<=0,0,ROUND(F14*J14,2)),"")} -> 382779.25
K31: Jumlah Total (A) | L31: {=SUM(L1:L30)} -> 1.7570024e+08 | M31: {=SUM(M1:M30)} -> 1.7552975e+08 | N31: {=SUM(N1:N30)} -> 1.7552975e+08
B32: HIT BPJS | D32: {=ROUND(IF(L32<=100000000,L32*0.24%,IF(AND(L32>100000000,L32<=500000000),100000000*0.24%+(L32-100000000)*0.19%,IF(AND(L32>500000000,L32<=1000000000),100000000*0.24%+400000000*0.19%+(L32-500000000)*0.15%,IF(AND(L32>1000000000,L32<=5000000000),100000000*0.24%+400000000*0.19%+500000000*0.15%+(L32-1000000000)*0.12%,IF(L32>5000000000,100000000*0.24%+400000000*0.19%+500000000*0.15%+4000000000*0.12%+(L32-5000000000)*0.1%,"Bingung komputer"))))),2)} -> 383102.56 | E32: {=ROUND(IF(M32<=100000000,M32*0.24%,IF(AND(M32>100000000,M32<=500000000),100000000*0.24%+(M32-100000000)*0.19%,IF(AND(M32>500000000,M32<=1000000000),100000000*0.24%+400000000*0.19%+(M32-500000000)*0.15%,IF(AND(M32>1000000000,M32<=5000000000),100000000*0.24%+400000000*0.19%+500000000*0.15%+(M32-1000000000)*0.12%,IF(M32>5000000000,100000000*0.24%+400000000*0.19%+500000000*0.15%+4000000000*0.12%+(M32-5000000000)*0.1%,"Bingung komputer"))))),2)} -> 382779.25 | F32: {=ROUND(IF(N32<=100000000,N32*0.24%,IF(AND(N32>100000000,N32<=500000000),100000000*0.24%+(N32-100000000)*0.19%,IF(AND(N32>500000000,N32<=1000000000),100000000*0.24%+400000000*0.19%+(N32-500000000)*0.15%,IF(AND(N32>1000000000,N32<=5000000000),100000000*0.24%+400000000*0.19%+500000000*0.15%+(N32-1000000000)*0.12%,IF(N32>5000000000,100000000*0.24%+400000000*0.19%+500000000*0.15%+4000000000*0.12%+(N32-5000000000)*0.1%,"Bingung komputer"))))),2)} -> 382779.25 | K32: {="Jumlah Terkena Pajak "&MAX(K3:K30)&"% (B)"} -> Jumlah Terkena Pajak 11,00% (B) | L32: {=SUMIF($K3:$K30,">0",L3:L30)} -> 1.7531714e+08 | M32: {=SUMIF($K3:$K30,">0",M3:M30)} -> 1.7514697e+08 | N32: {=SUMIF($K3:$K30,">0",N3:N30)} -> 1.7514697e+08
K33: {="PPN (C) = "&MAX(K3:K30)&"% x B"} -> PPN (C) = 11,00% x B | L33: {=L32*MAX($K3:$K30)%} -> 19284885 | M33: {=M32*MAX($K3:$K30)%} -> 19266167 | N33: {=N32*MAX($K3:$K30)%} -> 19266167
K34: Jumlah Total (D) = (A) + ( C ) | L34: {=L31+L33} -> 1.9498512e+08 | M34: {=M31+M33} -> 1.9479592e+08 | N34: {=N31+N33} -> 1.9479592e+08
K35: Jumlah Total dibulatkan (E) | L35: {=ROUNDDOWN(L34,2)} -> 1.9498512e+08 | M35: {=ROUNDDOWN(M34,2)} -> 1.9479592e+08 | N35: {=ROUNDDOWN(N34,-3)} -> 194795000

Sheet 49013206
A1: No. | B1: Uraian Pekerjaan | D1: Kuantitas | G1: Satuan | H1: Harga Satuan | K1: PAJAK | L1: JUMLAH
D2: HPS | E2: Penawaran | F2: Negoisasi | H2: HPS | I2: Penawaran | J2: Negoisasi | L2: HPS | M2: Penawaran | N2: Negoisasi
B3: DIVISI 1. UMUM | L3: {=IF(D3>0,IF($D3<=0,0,D3*H3),"")} | M3: {=IF(E3>0,IF($D3<=0,0,ROUND(E3*I3,2)),"")} | N3: {=IF(F3>0,IF($D3<=0,0,ROUND(F3*J3,2)),"")}
A4: 1.2 | B4: Mobilisasi | D4: 1 | E4: {=D4} -> 1 | F4: {=D4} -> 1 | G4: LS | H4: 27750000 | I4: 27710000 | J4: 27710000 | K4: 11 | L4: {=IF(D4>0,IF($D4<=0,0,D4*H4),"")} -> 27750000 | M4: {=IF(E4>0,IF($D4<=0,0,ROUND(E4*I4,2)),"")} -> 27710000 | N4: {=IF(F4>0,IF($D4<=0,0,ROUND(F4*J4,2)),"")} -> 27710000
B5: DIVISI 3. PEKERJAAN TANAH | L5: {=IF(D5>0,IF($D5<=0,0,D5*H5),"")} | M5: {=IF(E5>0,IF($D5<=0,0,ROUND(E5*I5,2)),"")} | N5: {=IF(F5>0,IF($D5<=0,0,ROUND(F5*J5,2)),"")}
A6: 3.2.(1a) | B6: Timbunan Biasa dari sumber galian | D6: 508 | E6: {=D6} -> 508 | F6: {=D6} -> 508 | G6: M3 | H6: 278997.31 | I6: 278997.31 | J6: 278997.31 | K6: 11 | L6: {=IF(D6>0,IF($D6<=0,0,D6*H6),"")} -> 1.4173063e+08 | M6: {=IF(E6>0,IF($D6<=0,0,ROUND(E6*I6,2)),"")} -> 1.4173063e+08 | N6: {=IF(F6>0,IF($D6<=0,0,ROUND(F6*J6,2)),"")} -> 1.4173063e+08
A7: 3.3.(1) | B7: Penyiapan Badan Jalan | D7: 3175 | E7: {=D7} -> 3175 | F7: {=D7} -> 3175 | G7: M3 | H7: 1817.45 | I7: 1816.25 | J7: 1816.25 | K7: 11 | L7: {=IF(D7>0,IF($D7<=0,0,D7*H7),"")} -> 5770403.8 | M7: {=IF(E7>0,IF($D7<=0,0,ROUND(E7*I7,2)),"")} -> 5766593.8 | N7: {=IF(F7>0,IF($D7<=0,0,ROUND(F7*J7,2)),"")} -> 5766593.8
B8: Biaya BPJS Ketenaga Kerjaan | L8: {=IF(D8>0,IF($D8<=0,0,D8*H8),"")}
A9: 1 | B9: JKK/JKM | D9: 1 | E9: {=D9} -> 1 | F9: {=D9} -> 1 | G9: LS | H9: 382977 | I9: 382894 | J9: 382894 | K9: 0 | L9: {=IF(D9>0,IF($D9<=0,0,D9*H9),"")} -> 382977 | M9: {=IF(E9>0,IF($D9<=0,0,ROUND(E9*I9,2)),"")} -> 382894 | N9: {=IF(F9>0,IF($D9<=0,0,ROUND(F9*J9,2)),"")} -> 382894
K26: Jumlah Total (A) | L26: {=SUM(L1:L25)} -> 1.7563401e+08 | M26: {=SUM(M1:M25)} -> 1.7559012e+08 | N26: {=SUM(N1:N25)} -> 1.7559012e+08
B27: HIT BPJS | D27: {=ROUND(IF(L27<=100000000,L27*0.24%,IF(AND(L27>100000000,L27<=500000000),100000000*0.24%+(L27-100000000)*0.19%,IF(AND(L27>500000000,L27<=1000000000),100000000*0.24%+400000000*0.19%+(L27-500000000)*0.15%,IF(AND(L27>1000000000,L27<=5000000000),100000000*0.24%+400000000*0.19%+500000000*0.15%+(L27-1000000000)*0.12%,IF(L27>5000000000,100000000*0.24%+400000000*0.19%+500000000*0.15%+4000000000*0.12%+(L27-5000000000)*0.1%,"Bingung komputer"))))),2)} -> 382976.97 | E27: {=ROUND(IF(M27<=100000000,M27*0.24%,IF(AND(M27>100000000,M27<=500000000),100000000*0.24%+(M27-100000000)*0.19%,IF(AND(M27>500000000,M27<=1000000000),100000000*0.24%+400000000*0.19%+(M27-500000000)*0.15%,IF(AND(M27>1000000000,M27<=5000000000),100000000*0.24%+400000000*0.19%+500000000*0.15%+(M27-1000000000)*0.12%,IF(M27>5000000000,100000000*0.24%+400000000*0.19%+500000000*0.15%+4000000000*0.12%+(M27-5000000000)*0.1%,"Bingung komputer"))))),2)} -> 382893.73 | F27: {=ROUND(IF(N27<=100000000,N27*0.24%,IF(AND(N27>100000000,N27<=500000000),100000000*0.24%+(N27-100000000)*0.19%,IF(AND(N27>500000000,N27<=1000000000),100000000*0.24%+400000000*0.19%+(N27-500000000)*0.15%,IF(AND(N27>1000000000,N27<=5000000000),100000000*0.24%+400000000*0.19%+500000000*0.15%+(N27-1000000000)*0.12%,IF(N27>5000000000,100000000*0.24%+400000000*0.19%+500000000*0.15%+4000000000*0.12%+(N27-5000000000)*0.1%,"Bingung komputer"))))),2)} -> 382893.73 | K27: {="Jumlah Terkena Pajak "&MAX(K3:K25)&"% (B)"} -> Jumlah Terkena Pajak 11,00% (B) | L27: {=SUMIF($K3:$K25,">0",L3:L25)} -> 1.7525104e+08 | M27: {=SUMIF($K3:$K25,">0",M3:M25)} -> 1.7520723e+08 | N27: {=SUMIF($K3:$K25,">0",N3:N25)} -> 1.7520723e+08
K28: {="PPN (C) = "&MAX(K3:K25)&"% x B"} -> PPN (C) = 11,00% x B | L28: {=L27*MAX($K3:$K25)%} -> 19277614 | M28: {=M27*MAX($K3:$K25)%} -> 19272795 | N28: {=N27*MAX($K3:$K25)%} -> 19272795
K29: Jumlah Total (D) = (A) + ( C ) | L29: {=L26+L28} -> 1.9491163e+08 | M29: {=M26+M28} -> 1.9486292e+08 | N29: {=N26+N28} -> 1.9486292e+08
K30: Jumlah Total dibulatkan (E) | L30: {=ROUNDDOWN(L29,2)} -> 1.9491163e+08 | M30: {=ROUNDDOWN(M29,2)} -> 1.9486292e+08 | N30: {=ROUNDDOWN(N29,-3)} -> 194862000

Sheet 49013151
A1: No. | B1: Uraian Pekerjaan | D1: Kuantitas | G1: Satuan | H1: Harga Satuan | K1: PAJAK | L1: JUMLAH
D2: HPS | E2: Penawaran | F2: Negoisasi | H2: HPS | I2: Penawaran | J2: Negoisasi | L2: HPS | M2: Penawaran | N2: Negoisasi
B3: DIVISI 1. UMUM | L3: {=IF(D3>0,IF($D3<=0,0,D3*H3),"")} | M3: {=IF(E3>0,IF($D3<=0,0,ROUND(E3*I3,2)),"")} | N3: {=IF(F3>0,IF($D3<=0,0,ROUND(F3*J3,2)),"")}
A4: 1.2 | B4: Mobilisasi | D4: 1 | E4: {=D4} -> 1 | F4: {=D4} -> 1 | G4: LS | H4: 27750000 | I4: 27670000 | J4: 27670000 | K4: 11 | L4: {=IF(D4>0,IF($D4<=0,0,D4*H4),"")} -> 27750000 | M4: {=IF(E4>0,IF($D4<=0,0,ROUND(E4*I4,2)),"")} -> 27670000 | N4: {=IF(F4>0,IF($D4<=0,0,ROUND(F4*J4,2)),"")} -> 27670000
B5: DIVISI 3. PEKERJAAN TANAH | L5: {=IF(D5>0,IF($D5<=0,0,D5*H5),"")} | M5: {=IF(E5>0,IF($D5<=0,0,ROUND(E5*I5,2)),"")} | N5: {=IF(F5>0,IF($D5<=0,0,ROUND(F5*J5,2)),"")}
A6: 3.2.(1a) | B6: Timbunan Biasa dari sumber galian | D6: 600 | E6: {=D6} -> 600 | F6: {=D6} -> 600 | G6: M3 | H6: 236046.98 | I6: 236046.98 | J6: 236046.98 | K6: 11 | L6: {=IF(D6>0,IF($D6<=0,0,D6*H6),"")} -> 141628188 | M6: {=IF(E6>0,IF($D6<=0,0,ROUND(E6*I6,2)),"")} -> 141628188 | N6: {=IF(F6>0,IF($D6<=0,0,ROUND(F6*J6,2)),"")} -> 141628188
A7: 3.3.(1) | B7: Penyiapan Badan Jalan | D7: 2700 | E7: {=D7} -> 2700 | F7: {=D7} -> 2700 | G7: M3 | H7: 2136.32 | I7: 2135.5 | J7: 2135.5 | K7: 11 | L7: {=IF(D7>0,IF($D7<=0,0,D7*H7),"")} -> 5768064 | M7: {=IF(E7>0,IF($D7<=0,0,ROUND(E7*I7,2)),"")} -> 5765850 | N7: {=IF(F7>0,IF($D7<=0,0,ROUND(F7*J7,2)),"")} -> 5765850
B8: Biaya BPJS Ketenaga Kerjaan | L8: {=IF(D8>0,IF($D8<=0,0,D8*H8),"")}
A9: 1 | B9: JKK/JKM | D9: 1 | E9: {=D9} -> 1 | F9: {=D9} -> 1 | G9: LS | H9: 382778 | I9: 382622 | J9: 382622 | K9: 0 | L9: {=IF(D9>0,IF($D9<=0,0,D9*H9),"")} -> 382778 | M9: {=IF(E9>0,IF($D9<=0,0,ROUND(E9*I9,2)),"")} -> 382622 | N9: {=IF(F9>0,IF($D9<=0,0,ROUND(F9*J9,2)),"")} -> 382622
K26: Jumlah Total (A) | L26: {=SUM(L1:L25)} -> 175529030 | M26: {=SUM(M1:M25)} -> 175446660 | N26: {=SUM(N1:N25)} -> 175446660
B27: HIT BPJS | D27: {=ROUND(IF(L27<=100000000,L27*0.24%,IF(AND(L27>100000000,L27<=500000000),100000000*0.24%+(L27-100000000)*0.19%,IF(AND(L27>500000000,L27<=1000000000),100000000*0.24%+400000000*0.19%+(L27-500000000)*0.15%,IF(AND(L27>1000000000,L27<=5000000000),100000000*0.24%+400000000*0.19%+500000000*0.15%+(L27-1000000000)*0.12%,IF(L27>5000000000,100000000*0.24%+400000000*0.19%+500000000*0.15%+4000000000*0.12%+(L27-5000000000)*0.1%,"Bingung komputer"))))),2)} -> 382777.88 | E27: {=ROUND(IF(M27<=100000000,M27*0.24%,IF(AND(M27>100000000,M27<=500000000),100000000*0.24%+(M27-100000000)*0.19%,IF(AND(M27>500000000,M27<=1000000000),100000000*0.24%+400000000*0.19%+(M27-500000000)*0.15%,IF(AND(M27>1000000000,M27<=5000000000),100000000*0.24%+400000000*0.19%+500000000*0.15%+(M27-1000000000)*0.12%,IF(M27>5000000000,100000000*0.24%+400000000*0.19%+500000000*0.15%+4000000000*0.12%+(M27-5000000000)*0.1%,"Bingung komputer"))))),2)} -> 382621.67 | F27: {=ROUND(IF(N27<=100000000,N27*0.24%,IF(AND(N27>100000000,N27<=500000000),100000000*0.24%+(N27-100000000)*0.19%,IF(AND(N27>500000000,N27<=1000000000),100000000*0.24%+400000000*0.19%+(N27-500000000)*0.15%,IF(AND(N27>1000000000,N27<=5000000000),100000000*0.24%+400000000*0.19%+500000000*0.15%+(N27-1000000000)*0.12%,IF(N27>5000000000,100000000*0.24%+400000000*0.19%+500000000*0.15%+4000000000*0.12%+(N27-5000000000)*0.1%,"Bingung komputer"))))),2)} -> 382621.67 | K27: {="Jumlah Terkena Pajak "&MAX(K3:K25)&"% (B)"} -> Jumlah Terkena Pajak 11,00% (B) | L27: {=SUMIF($K3:$K25,">0",L3:L25)} -> 175146252 | M27: {=SUMIF($K3:$K25,">0",M3:M25)} -> 175064038 | N27: {=SUMIF($K3:$K25,">0",N3:N25)} -> 175064038
K28: {="PPN (C) = "&MAX(K3:K25)&"% x B"} -> PPN (C) = 11,00% x B | L28: {=L27*MAX($K3:$K25)%} -> 19266088 | M28: {=M27*MAX($K3:$K25)%} -> 19257044 | N28: {=N27*MAX($K3:$K25)%} -> 19257044
K29: Jumlah Total (D) = (A) + ( C ) | L29: {=L26+L28} -> 1.9479512e+08 | M29: {=M26+M28} -> 1.947037e+08 | N29: {=N26+N28} -> 1.947037e+08
K30: Jumlah Total dibulatkan (E) | L30: {=ROUNDDOWN(L29,2)} -> 1.9479512e+08 | M30: {=ROUNDDOWN(M29,2)} -> 1.947037e+08 | N30: {=ROUNDDOWN(N29,-3)} -> 194703000

Sheet 49013260
A1: No. | B1: Uraian Pekerjaan | D1: Kuantitas | G1: Satuan | H1: Harga Satuan | K1: PAJAK | L1: JUMLAH
D2: HPS | E2: Penawaran | F2: Negoisasi | H2: HPS | I2: Penawaran | J2: Negoisasi | L2: HPS | M2: Penawaran | N2: Negoisasi
B3: DIVISI 1. UMUM | L3: {=IF(D3>0,IF($D3<=0,0,D3*H3),"")} | M3: {=IF(E3>0,IF($D3<=0,0,ROUND(E3*I3,2)),"")} | N3: {=IF(F3>0,IF($D3<=0,0,ROUND(F3*J3,2)),"")}
A4: 1.2 | B4: Mobilisasi | D4: 1 | E4: {=D4} -> 1 | F4: {=D4} -> 1 | G4: LS | H4: 27550000 | I4: 27510000 | J4: 27510000 | K4: 11 | L4: {=IF(D4>0,IF($D4<=0,0,D4*H4),"")} -> 27550000 | M4: {=IF(E4>0,IF($D4<=0,0,ROUND(E4*I4,2)),"")} -> 27510000 | N4: {=IF(F4>0,IF($D4<=0,0,ROUND(F4*J4,2)),"")} -> 27510000
B5: DIVISI 3. PEKERJAAN TANAH | L5: {=IF(D5>0,IF($D5<=0,0,D5*H5),"")} | M5: {=IF(E5>0,IF($D5<=0,0,ROUND(E5*I5,2)),"")} | N5: {=IF(F5>0,IF($D5<=0,0,ROUND(F5*J5,2)),"")}
A6: 3.2.(1a) | B6: Timbunan Biasa dari sumber galian | D6: 557.12 | E6: {=D6} -> 557.12 | F6: {=D6} -> 557.12 | G6: M3 | H6: 254663.92 | I6: 254663.92 | J6: 254663.92 | K6: 11 | L6: {=IF(D6>0,IF($D6<=0,0,D6*H6),"")} -> 1.4187836e+08 | M6: {=IF(E6>0,IF($D6<=0,0,ROUND(E6*I6,2)),"")} -> 1.4187836e+08 | N6: {=IF(F6>0,IF($D6<=0,0,ROUND(F6*J6,2)),"")} -> 1.4187836e+08
A7: 3.3.(1) | B7: Penyiapan Badan Jalan | D7: 3133.8 | E7: {=D7} -> 3133.8 | F7: {=D7} -> 3133.8 | G7: M2 | H7: 1816.48 | I7: 1816.07 | J7: 1816.07 | K7: 11 | L7: {=IF(D7>0,IF($D7<=0,0,D7*H7),"")} -> 5692485 | M7: {=IF(E7>0,IF($D7<=0,0,ROUND(E7*I7,2)),"")} -> 5691200.2 | N7: {=IF(F7>0,IF($D7<=0,0,ROUND(F7*J7,2)),"")} -> 5691200.2
B8: Biaya BPJS Ketenaga Kerjaan | L8: {=IF(D8>0,IF($D8<=0,0,D8*H8),"")}
A9: 1 | B9: JKK/JKM | D9: 1 | E9: {=D9} -> 1 | F9: {=D9} -> 1 | G9: LS | H9: 382730 | I9: 382651 | J9: 382651 | K9: 0 | L9: {=IF(D9>0,IF($D9<=0,0,D9*H9),"")} -> 382730 | M9: {=IF(E9>0,IF($D9<=0,0,ROUND(E9*I9,2)),"")} -> 382651 | N9: {=IF(F9>0,IF($D9<=0,0,ROUND(F9*J9,2)),"")} -> 382651
K26: Jumlah Total (A) | L26: {=SUM(L1:L25)} -> 1.7550358e+08 | M26: {=SUM(M1:M25)} -> 1.7546221e+08 | N26: {=SUM(N1:N25)} -> 1.7546221e+08
B27: HIT BPJS | D27: {=ROUND(IF(L27<=100000000,L27*0.24%,IF(AND(L27>100000000,L27<=500000000),100000000*0.24%+(L27-100000000)*0.19%,IF(AND(L27>500000000,L27<=1000000000),100000000*0.24%+400000000*0.19%+(L27-500000000)*0.15%,IF(AND(L27>1000000000,L27<=5000000000),100000000*0.24%+400000000*0.19%+500000000*0.15%+(L27-1000000000)*0.12%,IF(L27>5000000000,100000000*0.24%+400000000*0.19%+500000000*0.15%+4000000000*0.12%+(L27-5000000000)*0.1%,"Bingung komputer"))))),2)} -> 382729.61 | E27: {=ROUND(IF(M27<=100000000,M27*0.24%,IF(AND(M27>100000000,M27<=500000000),100000000*0.24%+(M27-100000000)*0.19%,IF(AND(M27>500000000,M27<=1000000000),100000000*0.24%+400000000*0.19%+(M27-500000000)*0.15%,IF(AND(M27>1000000000,M27<=5000000000),100000000*0.24%+400000000*0.19%+500000000*0.15%+(M27-1000000000)*0.12%,IF(M27>5000000000,100000000*0.24%+400000000*0.19%+500000000*0.15%+4000000000*0.12%+(M27-5000000000)*0.1%,"Bingung komputer"))))),2)} -> 382651.17 | F27: {=ROUND(IF(N27<=100000000,N27*0.24%,IF(AND(N27>100000000,N27<=500000000),100000000*0.24%+(N27-100000000)*0.19%,IF(AND(N27>500000000,N27<=1000000000),100000000*0.24%+400000000*0.19%+(N27-500000000)*0.15%,IF(AND(N27>1000000000,N27<=5000000000),100000000*0.24%+400000000*0.19%+500000000*0.15%+(N27-1000000000)*0.12%,IF(N27>5000000000,100000000*0.24%+400000000*0.19%+500000000*0.15%+4000000000*0.12%+(N27-5000000000)*0.1%,"Bingung komputer"))))),2)} -> 382651.17 | K27: {="Jumlah Terkena Pajak "&MAX(K3:K25)&"% (B)"} -> Jumlah Terkena Pajak 11,00% (B) | L27: {=SUMIF($K3:$K25,">0",L3:L25)} -> 1.7512085e+08 | M27: {=SUMIF($K3:$K25,">0",M3:M25)} -> 1.7507956e+08 | N27: {=SUMIF($K3:$K25,">0",N3:N25)} -> 1.7507956e+08
K28: {="PPN (C) = "&MAX(K3:K25)&"% x B"} -> PPN (C) = 11,00% x B | L28: {=L27*MAX($K3:$K25)%} -> 19263293 | M28: {=M27*MAX($K3:$K25)%} -> 19258752 | N28: {=N27*MAX($K3:$K25)%} -> 19258752
K29: Jumlah Total (D) = (A) + ( C ) | L29: {=L26+L28} -> 1.9476687e+08 | M29: {=M26+M28} -> 1.9472097e+08 | N29: {=N26+N28} -> 1.9472097e+08
K30: Jumlah Total dibulatkan (E) | L30: {=ROUNDDOWN(L29,2)} -> 1.9476687e+08 | M30: {=ROUNDDOWN(M29,2)} -> 1.9472097e+08 | N30: {=ROUNDDOWN(N29,-3)} -> 194720000

Sheet 49015188
A1: No. | B1: Uraian Pekerjaan | D1: Kuantitas | G1: Satuan | H1: Harga Satuan | K1: PAJAK | L1: JUMLAH
D2: HPS | E2: Penawaran | F2: Negoisasi | H2: HPS | I2: Penawaran | J2: Negoisasi | L2: HPS | M2: Penawaran | N2: Negoisasi
A3: A | B3: BIAYA LANGSUNG PERSONIL | L3: {=IF(D3>0,IF($D3<=0,0,D3*H3),"")} | M3: {=IF(E3>0,IF($D3<=0,0,ROUND(E3*I3,2)),"")} | N3: {=IF(F3>0,IF($D3<=0,0,ROUND(F3*J3,2)),"")}
A4: I | B4: PROFESIONAL STAFF/SUB PROFESIONAL STAFF | L4: {=IF(D4>0,IF($D4<=0,0,D4*H4),"")} | M4: {=IF(E4>0,IF($D4<=0,0,ROUND(E4*I4,2)),"")} | N4: {=IF(F4>0,IF($D4<=0,0,ROUND(F4*J4,2)),"")}
A5: 1 | B5: Team Leader (Ahli Teknik Jalan) | D5: 4.5 | E5: {=D5} -> 4.5 | F5: {=D5} -> 4.5 | G5: Orang/Bln | H5: 9000000 | I5: 8980000 | J5: 8980000 | K5: 11 | L5: {=IF(D5>0,IF($D5<=0,0,D5*H5),"")} -> 40500000 | M5: {=IF(E5>0,IF($D5<=0,0,ROUND(E5*I5,2)),"")} -> 40410000 | N5: {=IF(F5>0,IF($D5<=0,0,ROUND(F5*J5,2)),"")} -> 40410000
A6: 2 | B6: Inspektur/pengawas Jalan ( 1 0rang) | D6: 4.5 | E6: {=D6} -> 4.5 | F6: {=D6} -> 4.5 | G6: Orang/Bln | H6: 2500000 | I6: 2500000 | J6: 2500000 | K6: 11 | L6: {=IF(D6>0,IF($D6<=0,0,D6*H6),"")} -> 11250000 | M6: {=IF(E6>0,IF($D6<=0,0,ROUND(E6*I6,2)),"")} -> 11250000 | N6: {=IF(F6>0,IF($D6<=0,0,ROUND(F6*J6,2)),"")} -> 11250000
A7: B | B7: BIAYA LANGSUNG NON PERSONIL | L7: {=IF(D7>0,IF($D7<=0,0,D7*H7),"")} | M7: {=IF(E7>0,IF($D7<=0,0,ROUND(E7*I7,2)),"")} | N7: {=IF(F7>0,IF($D7<=0,0,ROUND(F7*J7,2)),"")}
A8: I | B8: KANTOR, AKOMODASI DAN PERALATAN | L8: {=IF(D8>0,IF($D8<=0,0,D8*H8),"")} | M8: {=IF(E8>0,IF($D8<=0,0,ROUND(E8*I8,2)),"")} | N8: {=IF(F8>0,IF($D8<=0,0,ROUND(F8*J8,2)),"")}
A9: 1 | B9: Sewa Printer A4 | D9: 4.5 | E9: {=D9} -> 4.5 | F9: {=D9} -> 4.5 | G9: unit-Bulan | H9: 200000 | I9: 200000 | J9: 200000 | K9: 11 | L9: {=IF(D9>0,IF($D9<=0,0,D9*H9),"")} -> 900000 | M9: {=IF(E9>0,IF($D9<=0,0,ROUND(E9*I9,2)),"")} -> 900000 | N9: {=IF(F9>0,IF($D9<=0,0,ROUND(F9*J9,2)),"")} -> 900000
A10: 2 | B10: ATK, Tinta Printer, akomodasi, listrik & telepon/Internet | D10: 4.5 | E10: {=D10} -> 4.5 | F10: {=D10} -> 4.5 | G10: Bulan | H10: 1000000 | I10: 1000000 | J10: 1000000 | K10: 11 | L10: {=IF(D10>0,IF($D10<=0,0,D10*H10),"")} -> 4500000 | M10: {=IF(E10>0,IF($D10<=0,0,ROUND(E10*I10,2)),"")} -> 4500000 | N10: {=IF(F10>0,IF($D10<=0,0,ROUND(F10*J10,2)),"")} -> 4500000
A11: 3 | B11: Sewa Laptop | D11: 4.5 | E11: {=D11} -> 4.5 | F11: {=D11} -> 4.5 | G11: unit-Bulan | H11: 500000 | I11: 500000 | J11: 500000 | K11: 11 | L11: {=IF(D11>0,IF($D11<=0,0,D11*H11),"")} -> 2250000 | M11: {=IF(E11>0,IF($D11<=0,0,ROUND(E11*I11,2)),"")} -> 2250000 | N11: {=IF(F11>0,IF($D11<=0,0,ROUND(F11*J11,2)),"")} -> 2250000
B12: BIAYA SMK3 | L12: {=IF(D12>0,IF($D12<=0,0,D12*H12),"")} | M12: {=IF(E12>0,IF($D12<=0,0,ROUND(E12*I12,2)),"")} | N12: {=IF(F12>0,IF($D12<=0,0,ROUND(F12*J12,2)),"")}
A13: 4 | B13: Helem Proyek | D13: 2 | E13: {=D13} -> 2 | F13: {=D13} -> 2 | G13: buah | H13: 77000 | I13: 70000 | J13: 70000 | K13: 11 | L13: {=IF(D13>0,IF($D13<=0,0,D13*H13),"")} -> 154000 | M13: {=IF(E13>0,IF($D13<=0,0,ROUND(E13*I13,2)),"")} -> 140000 | N13: {=IF(F13>0,IF($D13<=0,0,ROUND(F13*J13,2)),"")} -> 140000
A14: 5 | B14: Sepatu Safety | D14: 2 | E14: {=D14} -> 2 | F14: {=D14} -> 2 | G14: buah | H14: 250000 | I14: 250000 | J14: 250000 | K14: 11 | L14: {=IF(D14>0,IF($D14<=0,0,D14*H14),"")} -> 500000 | M14: {=IF(E14>0,IF($D14<=0,0,ROUND(E14*I14,2)),"")} -> 500000 | N14: {=IF(F14>0,IF($D14<=0,0,ROUND(F14*J14,2)),"")} -> 500000
B15: BIAYA SEWA KENDARAAN/TRANSPORTASI | L15: {=IF(D15>0,IF($D15<=0,0,D15*H15),"")} | M15: {=IF(E15>0,IF($D15<=0,0,ROUND(E15*I15,2)),"")} | N15: {=IF(F15>0,IF($D15<=0,0,ROUND(F15*J15,2)),"")}
A16: II | B16: Sewa & Ops. Kendaraan (1 unit) | D16: 4.5 | E16: {=D16} -> 4.5 | F16: {=D16} -> 4.5 | G16: Unit Bulan | H16: 625000 | I16: 610000 | J16: 610000 | K16: 11 | L16: {=IF(D16>0,IF($D16<=0,0,D16*H16),"")} -> 2812500 | M16: {=IF(E16>0,IF($D16<=0,0,ROUND(E16*I16,2)),"")} -> 2745000 | N16: {=IF(F16>0,IF($D16<=0,0,ROUND(F16*J16,2)),"")} -> 2745000
A17: 1 | B17: Laporan Pendahuluan | D17: 3 | E17: {=D17} -> 3 | F17: {=D17} -> 3 | G17: rangkap | H17: 200000 | I17: 200000 | J17: 200000 | K17: 11 | L17: {=IF(D17>0,IF($D17<=0,0,D17*H17),"")} -> 600000 | M17: {=IF(E17>0,IF($D17<=0,0,ROUND(E17*I17,2)),"")} -> 600000 | N17: {=IF(F17>0,IF($D17<=0,0,ROUND(F17*J17,2)),"")} -> 600000
A18: 2 | B18: Laporan Bulanan | D18: 9 | E18: {=D18} -> 9 | F18: {=D18} -> 9 | G18: rangkap | H18: 150000 | I18: 150000 | J18: 150000 | K18: 11 | L18: {=IF(D18>0,IF($D18<=0,0,D18*H18),"")} -> 1350000 | M18: {=IF(E18>0,IF($D18<=0,0,ROUND(E18*I18,2)),"")} -> 1350000 | N18: {=IF(F18>0,IF($D18<=0,0,ROUND(F18*J18,2)),"")} -> 1350000
A19: 3 | B19: Laporan Akhir | D19: 3 | E19: {=D19} -> 3 | F19: {=D19} -> 3 | G19: rangkap | H19: 200000 | I19: 200000 | J19: 200000 | K19: 11 | L19: {=IF(D19>0,IF($D19<=0,0,D19*H19),"")} -> 600000 | M19: {=IF(E19>0,IF($D19<=0,0,ROUND(E19*I19,2)),"")} -> 600000 | N19: {=IF(F19>0,IF($D19<=0,0,ROUND(F19*J19,2)),"")} -> 600000
A20: 4 | B20: SSD External 1 TB | D20: 1 | E20: {=D20} -> 1 | F20: {=D20} -> 1 | G20: Buah | H20: 2000000 | I20: 2000000 | J20: 2000000 | K20: 11 | L20: {=IF(D20>0,IF($D20<=0,0,D20*H20),"")} -> 2000000 | M20: {=IF(E20>0,IF($D20<=0,0,ROUND(E20*I20,2)),"")} -> 2000000 | N20: {=IF(F20>0,IF($D20<=0,0,ROUND(F20*J20,2)),"")} -> 2000000
A21: V | B21: BPJS | L21: {=IF(D21>0,IF($D21<=0,0,D21*H21),"")} | M21: {=IF(E21>0,IF($D21<=0,0,ROUND(E21*I21,2)),"")} | N21: {=IF(F21>0,IF($D21<=0,0,ROUND(F21*J21,2)),"")}
B22: NKKK = 100.000.000,- | D22: 1 | E22: {=D22} -> 1 | F22: {=D22} -> 1 | G22: LS | H22: 161799.6 | I22: 161388 | J22: 161388 | K22: 0 | L22: {=IF(D22>0,IF($D22<=0,0,D22*H22),"")} -> 161799.6 | M22: {=IF(E22>0,IF($D22<=0,0,ROUND(E22*I22,2)),"")} -> 161388 | N22: {=IF(F22>0,IF($D22<=0,0,ROUND(F22*J22,2)),"")} -> 161388
L23: {=IF(D23>0,IF($D23<=0,0,D23*H23),"")} | M23: {=IF(E23>0,IF($D23<=0,0,ROUND(E23*I23,2)),"")} | N23: {=IF(F23>0,IF($D23<=0,0,ROUND(F23*J23,2)),"")}
K24: Jumlah Total (A) | L24: {=SUM(L1:L23)} -> 67578300 | M24: {=SUM(M1:M23)} -> 67406388 | N24: {=SUM(N1:N23)} -> 67406388
B25: HIT BPJS | D25: {=ROUND(IF(L25<=100000000,L25*0.24%,IF(AND(L25>100000000,L25<=500000000),100000000*0.24%+(L25-100000000)*0.19%,IF(AND(L25>500000000,L25<=1000000000),100000000*0.24%+400000000*0.19%+(L25-500000000)*0.15%,IF(AND(L25>1000000000,L25<=5000000000),100000000*0.24%+400000000*0.19%+500000000*0.15%+(L25-1000000000)*0.12%,IF(L25>5000000000,100000000*0.24%+400000000*0.19%+500000000*0.15%+4000000000*0.12%+(L25-5000000000)*0.1%,"Bingung komputer"))))),2)} -> 161799.6 | E25: {=ROUND(IF(M25<=100000000,M25*0.24%,IF(AND(M25>100000000,M25<=500000000),100000000*0.24%+(M25-100000000)*0.19%,IF(AND(M25>500000000,M25<=1000000000),100000000*0.24%+400000000*0.19%+(M25-500000000)*0.15%,IF(AND(M25>1000000000,M25<=5000000000),100000000*0.24%+400000000*0.19%+500000000*0.15%+(M25-1000000000)*0.12%,IF(M25>5000000000,100000000*0.24%+400000000*0.19%+500000000*0.15%+4000000000*0.12%+(M25-5000000000)*0.1%,"Bingung komputer"))))),2)} -> 161388 | F25: {=ROUND(IF(N25<=100000000,N25*0.24%,IF(AND(N25>100000000,N25<=500000000),100000000*0.24%+(N25-100000000)*0.19%,IF(AND(N25>500000000,N25<=1000000000),100000000*0.24%+400000000*0.19%+(N25-500000000)*0.15%,IF(AND(N25>1000000000,N25<=5000000000),100000000*0.24%+400000000*0.19%+500000000*0.15%+(N25-1000000000)*0.12%,IF(N25>5000000000,100000000*0.24%+400000000*0.19%+500000000*0.15%+4000000000*0.12%+(N25-5000000000)*0.1%,"Bingung komputer"))))),2)} -> 161388 | K25: {="Jumlah Terkena Pajak "&MAX(K3:K23)&"% (B)"} -> Jumlah Terkena Pajak 11,00% (B) | L25: {=SUMIF($K3:$K23,">0",L3:L23)} -> 67416500 | M25: {=SUMIF($K3:$K23,">0",M3:M23)} -> 67245000 | N25: {=SUMIF($K3:$K23,">0",N3:N23)} -> 67245000
K26: {="PPN (C) = "&MAX(K3:K23)&"% x B"} -> PPN (C) = 11,00% x B | L26: {=L25*MAX($K3:$K23)%} -> 7415815 | M26: {=M25*MAX($K3:$K23)%} -> 7396950 | N26: {=N25*MAX($K3:$K23)%} -> 7396950
K27: Jumlah Total (D) = (A) + ( C ) | L27: {=L24+L26} -> 74994115 | M27: {=M24+M26} -> 74803338 | N27: {=N24+N26} -> 74803338
K28: Jumlah Total dibulatkan (E) | L28: {=ROUNDDOWN(L27,2)} -> 74994115 | M28: {=ROUNDDOWN(M27,2)} -> 74803338 | N28: {=ROUNDDOWN(N27,-3)} -> 74803000

Sheet 49015289
A1: No. | B1: Uraian Pekerjaan | D1: Kuantitas | G1: Satuan | H1: Harga Satuan | K1: PAJAK | L1: JUMLAH
D2: HPS | E2: Penawaran | F2: Negoisasi | H2: HPS | I2: Penawaran | J2: Negoisasi | L2: HPS | M2: Penawaran | N2: Negoisasi
A3: A | B3: BIAYA LANGSUNG PERSONIL | L3: {=IF(D3>0,IF($D3<=0,0,D3*H3),"")} | M3: {=IF(E3>0,IF($D3<=0,0,ROUND(E3*I3,2)),"")} | N3: {=IF(F3>0,IF($D3<=0,0,ROUND(F3*J3,2)),"")}
A4: I | B4: PROFESIONAL STAFF/SUB PROFESIONAL STAFF | L4: {=IF(D4>0,IF($D4<=0,0,D4*H4),"")} | M4: {=IF(E4>0,IF($D4<=0,0,ROUND(E4*I4,2)),"")} | N4: {=IF(F4>0,IF($D4<=0,0,ROUND(F4*J4,2)),"")}
A5: 1 | B5: Team Leader/Inspektur/pengawas (Ahli Teknik Jalan) | D5: 5 | E5: {=D5} -> 5 | F5: {=D5} -> 5 | G5: Orang/Bln | H5: 6500000 | I5: 6470000 | J5: 6470000 | K5: 11 | L5: {=IF(D5>0,IF($D5<=0,0,D5*H5),"")} -> 32500000 | M5: {=IF(E5>0,IF($D5<=0,0,ROUND(E5*I5,2)),"")} -> 32350000 | N5: {=IF(F5>0,IF($D5<=0,0,ROUND(F5*J5,2)),"")} -> 32350000
A6: B | B6: BIAYA LANGSUNG NON PERSONIL | L6: {=IF(D6>0,IF($D6<=0,0,D6*H6),"")} | M6: {=IF(E6>0,IF($D6<=0,0,ROUND(E6*I6,2)),"")} | N6: {=IF(F6>0,IF($D6<=0,0,ROUND(F6*J6,2)),"")}
A7: I | B7: KANTOR, AKOMODASI DAN PERALATAN | L7: {=IF(D7>0,IF($D7<=0,0,D7*H7),"")} | M7: {=IF(E7>0,IF($D7<=0,0,ROUND(E7*I7,2)),"")} | N7: {=IF(F7>0,IF($D7<=0,0,ROUND(F7*J7,2)),"")}
A8: 1 | B8: Sewa Printer A4 | D8: 1 | E8: {=D8} -> 1 | F8: {=D8} -> 1 | G8: LS | H8: 1270000 | I8: 1250000 | J8: 1250000 | K8: 11 | L8: {=IF(D8>0,IF($D8<=0,0,D8*H8),"")} -> 1270000 | M8: {=IF(E8>0,IF($D8<=0,0,ROUND(E8*I8,2)),"")} -> 1250000 | N8: {=IF(F8>0,IF($D8<=0,0,ROUND(F8*J8,2)),"")} -> 1250000
A9: 2 | B9: ATK, Tinta Printer, akomodasi, listrik & telepon/Internet | D9: 1 | E9: {=D9} -> 1 | F9: {=D9} -> 1 | G9: LS | H9: 3000000 | I9: 3000000 | J9: 3000000 | K9: 11 | L9: {=IF(D9>0,IF($D9<=0,0,D9*H9),"")} -> 3000000 | M9: {=IF(E9>0,IF($D9<=0,0,ROUND(E9*I9,2)),"")} -> 3000000 | N9: {=IF(F9>0,IF($D9<=0,0,ROUND(F9*J9,2)),"")} -> 3000000
A10: 3 | B10: Sewa Laptop | D10: 1 | E10: {=D10} -> 1 | F10: {=D10} -> 1 | G10: LS | H10: 1000000 | I10: 1000000 | J10: 1000000 | K10: 11 | L10: {=IF(D10>0,IF($D10<=0,0,D10*H10),"")} -> 1000000 | M10: {=IF(E10>0,IF($D10<=0,0,ROUND(E10*I10,2)),"")} -> 1000000 | N10: {=IF(F10>0,IF($D10<=0,0,ROUND(F10*J10,2)),"")} -> 1000000
B11: BIAYA SMK3 | L11: {=IF(D11>0,IF($D11<=0,0,D11*H11),"")} | M11: {=IF(E11>0,IF($D11<=0,0,ROUND(E11*I11,2)),"")} | N11: {=IF(F11>0,IF($D11<=0,0,ROUND(F11*J11,2)),"")}
A12: 4 | B12: Helem Proyek | D12: 1 | E12: {=D12} -> 1 | F12: {=D12} -> 1 | G12: buah | H12: 77000 | I12: 70000 | J12: 70000 | K12: 11 | L12: {=IF(D12>0,IF($D12<=0,0,D12*H12),"")} -> 77000 | M12: {=IF(E12>0,IF($D12<=0,0,ROUND(E12*I12,2)),"")} -> 70000 | N12: {=IF(F12>0,IF($D12<=0,0,ROUND(F12*J12,2)),"")} -> 70000
A13: 5 | B13: Sepatu Safety | D13: 1 | E13: {=D13} -> 1 | F13: {=D13} -> 1 | G13: buah | H13: 250000 | I13: 250000 | J13: 250000 | K13: 11 | L13: {=IF(D13>0,IF($D13<=0,0,D13*H13),"")} -> 250000 | M13: {=IF(E13>0,IF($D13<=0,0,ROUND(E13*I13,2)),"")} -> 250000 | N13: {=IF(F13>0,IF($D13<=0,0,ROUND(F13*J13,2)),"")} -> 250000
B14: BIAYA SEWA KENDARAAN/TRANSPORTASI | L14: {=IF(D14>0,IF($D14<=0,0,D14*H14),"")} | M14: {=IF(E14>0,IF($D14<=0,0,ROUND(E14*I14,2)),"")} | N14: {=IF(F14>0,IF($D14<=0,0,ROUND(F14*J14,2)),"")}
A15: 1 | B15: Sewa & Ops. Kendaraan (1 unit) | D15: 1 | E15: {=D15} -> 1 | F15: {=D15} -> 1 | G15: LS | H15: 2500000 | I15: 2500000 | J15: 2500000 | K15: 11 | L15: {=IF(D15>0,IF($D15<=0,0,D15*H15),"")} -> 2500000 | M15: {=IF(E15>0,IF($D15<=0,0,ROUND(E15*I15,2)),"")} -> 2500000 | N15: {=IF(F15>0,IF($D15<=0,0,ROUND(F15*J15,2)),"")} -> 2500000
A16: 2 | B16: Laporan Pendahuluan | D16: 3 | E16: {=D16} -> 3 | F16: {=D16} -> 3 | G16: rangkap | H16: 200000 | I16: 200000 | J16: 200000 | K16: 11 | L16: {=IF(D16>0,IF($D16<=0,0,D16*H16),"")} -> 600000 | M16: {=IF(E16>0,IF($D16<=0,0,ROUND(E16*I16,2)),"")} -> 600000 | N16: {=IF(F16>0,IF($D16<=0,0,ROUND(F16*J16,2)),"")} -> 600000
A17: 3 | B17: Laporan Bulanan | D17: 9 | E17: {=D17} -> 9 | F17: {=D17} -> 9 | G17: rangkap | H17: 150000 | I17: 150000 | J17: 150000 | K17: 11 | L17: {=IF(D17>0,IF($D17<=0,0,D17*H17),"")} -> 1350000 | M17: {=IF(E17>0,IF($D17<=0,0,ROUND(E17*I17,2)),"")} -> 1350000 | N17: {=IF(F17>0,IF($D17<=0,0,ROUND(F17*J17,2)),"")} -> 1350000
A18: 4 | B18: Laporan Akhir | D18: 3 | E18: {=D18} -> 3 | F18: {=D18} -> 3 | G18: rangkap | H18: 200000 | I18: 200000 | J18: 200000 | K18: 11 | L18: {=IF(D18>0,IF($D18<=0,0,D18*H18),"")} -> 600000 | M18: {=IF(E18>0,IF($D18<=0,0,ROUND(E18*I18,2)),"")} -> 600000 | N18: {=IF(F18>0,IF($D18<=0,0,ROUND(F18*J18,2)),"")} -> 600000
A19: 5 | B19: SSD External 1 TB | D19: 1 | E19: {=D19} -> 1 | F19: {=D19} -> 1 | G19: Buah | H19: 1800000 | I19: 1800000 | J19: 1800000 | K19: 11 | L19: {=IF(D19>0,IF($D19<=0,0,D19*H19),"")} -> 1800000 | M19: {=IF(E19>0,IF($D19<=0,0,ROUND(E19*I19,2)),"")} -> 1800000 | N19: {=IF(F19>0,IF($D19<=0,0,ROUND(F19*J19,2)),"")} -> 1800000
A20: V | B20: BPJS | L20: {=IF(D20>0,IF($D20<=0,0,D20*H20),"")} | M20: {=IF(E20>0,IF($D20<=0,0,ROUND(E20*I20,2)),"")} | N20: {=IF(F20>0,IF($D20<=0,0,ROUND(F20*J20,2)),"")}
B21: NKKK = 100.000.000,- | D21: 1 | E21: {=D21} -> 1 | F21: {=D21} -> 1 | G21: LS | H21: 107872.8 | I21: 107448 | J21: 107448 | K21: 0 | L21: {=IF(D21>0,IF($D21<=0,0,D21*H21),"")} -> 107872.8 | M21: {=IF(E21>0,IF($D21<=0,0,ROUND(E21*I21,2)),"")} -> 107448 | N21: {=IF(F21>0,IF($D21<=0,0,ROUND(F21*J21,2)),"")} -> 107448
L22: {=IF(D22>0,IF($D22<=0,0,D22*H22),"")} | M22: {=IF(E22>0,IF($D22<=0,0,ROUND(E22*I22,2)),"")} | N22: {=IF(F22>0,IF($D22<=0,0,ROUND(F22*J22,2)),"")}
K23: Jumlah Total (A) | L23: {=SUM(L1:L22)} -> 45054873 | M23: {=SUM(M1:M22)} -> 44877448 | N23: {=SUM(N1:N22)} -> 44877448
B24: HIT BPJS | D24: {=ROUND(IF(L24<=100000000,L24*0.24%,IF(AND(L24>100000000,L24<=500000000),100000000*0.24%+(L24-100000000)*0.19%,IF(AND(L24>500000000,L24<=1000000000),100000000*0.24%+400000000*0.19%+(L24-500000000)*0.15%,IF(AND(L24>1000000000,L24<=5000000000),100000000*0.24%+400000000*0.19%+500000000*0.15%+(L24-1000000000)*0.12%,IF(L24>5000000000,100000000*0.24%+400000000*0.19%+500000000*0.15%+4000000000*0.12%+(L24-5000000000)*0.1%,"Bingung komputer"))))),2)} -> 107872.8 | E24: {=ROUND(IF(M24<=100000000,M24*0.24%,IF(AND(M24>100000000,M24<=500000000),100000000*0.24%+(M24-100000000)*0.19%,IF(AND(M24>500000000,M24<=1000000000),100000000*0.24%+400000000*0.19%+(M24-500000000)*0.15%,IF(AND(M24>1000000000,M24<=5000000000),100000000*0.24%+400000000*0.19%+500000000*0.15%+(M24-1000000000)*0.12%,IF(M24>5000000000,100000000*0.24%+400000000*0.19%+500000000*0.15%+4000000000*0.12%+(M24-5000000000)*0.1%,"Bingung komputer"))))),2)} -> 107448 | F24: {=ROUND(IF(N24<=100000000,N24*0.24%,IF(AND(N24>100000000,N24<=500000000),100000000*0.24%+(N24-100000000)*0.19%,IF(AND(N24>500000000,N24<=1000000000),100000000*0.24%+400000000*0.19%+(N24-500000000)*0.15%,IF(AND(N24>1000000000,N24<=5000000000),100000000*0.24%+400000000*0.19%+500000000*0.15%+(N24-1000000000)*0.12%,IF(N24>5000000000,100000000*0.24%+400000000*0.19%+500000000*0.15%+4000000000*0.12%+(N24-5000000000)*0.1%,"Bingung komputer"))))),2)} -> 107448 | K24: {="Jumlah Terkena Pajak "&MAX(K3:K22)&"% (B)"} -> Jumlah Terkena Pajak 11,00% (B) | L24: {=SUMIF($K3:$K22,">0",L3:L22)} -> 44947000 | M24: {=SUMIF($K3:$K22,">0",M3:M22)} -> 44770000 | N24: {=SUMIF($K3:$K22,">0",N3:N22)} -> 44770000
K25: {="PPN (C) = "&MAX(K3:K22)&"% x B"} -> PPN (C) = 11,00% x B | L25: {=L24*MAX($K3:$K22)%} -> 4944170 | M25: {=M24*MAX($K3:$K22)%} -> 4924700 | N25: {=N24*MAX($K3:$K22)%} -> 4924700
K26: Jumlah Total (D) = (A) + ( C ) | L26: {=L23+L25} -> 49999043 | M26: {=M23+M25} -> 49802148 | N26: {=N23+N25} -> 49802148
K27: Jumlah Total dibulatkan (E) | L27: {=ROUNDDOWN(L26,2)} -> 49999043 | M27: {=ROUNDDOWN(M26,2)} -> 49802148 | N27: {=ROUNDDOWN(N26,-3)} -> 49802000

Sheet 49013313
A1: No. | B1: Uraian Pekerjaan | D1: Kuantitas | G1: Satuan | H1: Harga Satuan | K1: PAJAK | L1: JUMLAH
D2: HPS | E2: Penawaran | F2: Negoisasi | H2: HPS | I2: Penawaran | J2: Negoisasi | L2: HPS | M2: Penawaran | N2: Negoisasi
B3: DIVISI 1. UMUM | L3: {=IF(D3>0,IF($D3<=0,0,D3*H3),"")} | M3: {=IF(E3>0,IF($D3<=0,0,ROUND(E3*I3,2)),"")} | N3: {=IF(F3>0,IF($D3<=0,0,ROUND(F3*J3,2)),"")}
A4: 1.2 | B4: Mobilisasi | D4: 1 | E4: {=D4} -> 1 | F4: {=D4} -> 1 | G4: LS | H4: 27550000 | I4: 27470000 | J4: 27470000 | K4: 11 | L4: {=IF(D4>0,IF($D4<=0,0,D4*H4),"")} -> 27550000 | M4: {=IF(E4>0,IF($D4<=0,0,ROUND(E4*I4,2)),"")} -> 27470000 | N4: {=IF(F4>0,IF($D4<=0,0,ROUND(F4*J4,2)),"")} -> 27470000
B5: DIVISI 3. PEKERJAAN TANAH | L5: {=IF(D5>0,IF($D5<=0,0,D5*H5),"")} | M5: {=IF(E5>0,IF($D5<=0,0,ROUND(E5*I5,2)),"")} | N5: {=IF(F5>0,IF($D5<=0,0,ROUND(F5*J5,2)),"")}
A6: 3.1.(1a) | B6: Galian Biasa (Cuttingan) | D6: 1196 | E6: {=D6} -> 1196 | F6: {=D6} -> 1196 | G6: M3 | H6: 36207.05 | I6: 36198.66 | J6: 36198.66 | K6: 11 | L6: {=IF(D6>0,IF($D6<=0,0,D6*H6),"")} -> 43303632 | M6: {=IF(E6>0,IF($D6<=0,0,ROUND(E6*I6,2)),"")} -> 43293597 | N6: {=IF(F6>0,IF($D6<=0,0,ROUND(F6*J6,2)),"")} -> 43293597
A7: 3.2.(1a) | B7: Timbunan Biasa dari sumber galian | D7: 564.8 | E7: {=D7} -> 564.8 | F7: {=D7} -> 564.8 | G7: M3 | H7: 174503.35 | I7: 174503.35 | J7: 174503.35 | K7: 11 | L7: {=IF(D7>0,IF($D7<=0,0,D7*H7),"")} -> 98559492 | M7: {=IF(E7>0,IF($D7<=0,0,ROUND(E7*I7,2)),"")} -> 98559492 | N7: {=IF(F7>0,IF($D7<=0,0,ROUND(F7*J7,2)),"")} -> 98559492
A8: 3.3.(1) | B8: Penyiapan Badan Jalan | D8: 3177 | E8: {=D8} -> 3177 | F8: {=D8} -> 3177 | G8: M2 | H8: 1816.48 | I8: 1816.07 | J8: 1816.07 | K8: 11 | L8: {=IF(D8>0,IF($D8<=0,0,D8*H8),"")} -> 5770957 | M8: {=IF(E8>0,IF($D8<=0,0,ROUND(E8*I8,2)),"")} -> 5769654.4 | N8: {=IF(F8>0,IF($D8<=0,0,ROUND(F8*J8,2)),"")} -> 5769654.4
B9: Biaya BPJS Ketenaga Kerjaan | L9: {=IF(D9>0,IF($D9<=0,0,D9*H9),"")}
A10: 1 | B10: JKK/JKM | D10: 1 | E10: {=D10} -> 1 | F10: {=D10} -> 1 | G10: LS | H10: 382850 | I10: 382676 | J10: 382676 | K10: 0 | L10: {=IF(D10>0,IF($D10<=0,0,D10*H10),"")} -> 382850 | M10: {=IF(E10>0,IF($D10<=0,0,ROUND(E10*I10,2)),"")} -> 382676 | N10: {=IF(F10>0,IF($D10<=0,0,ROUND(F10*J10,2)),"")} -> 382676
K27: Jumlah Total (A) | L27: {=SUM(L1:L26)} -> 1.7556693e+08 | M27: {=SUM(M1:M26)} -> 1.7547542e+08 | N27: {=SUM(N1:N26)} -> 1.7547542e+08
B28: HIT BPJS | D28: {=ROUND(IF(L28<=100000000,L28*0.24%,IF(AND(L28>100000000,L28<=500000000),100000000*0.24%+(L28-100000000)*0.19%,IF(AND(L28>500000000,L28<=1000000000),100000000*0.24%+400000000*0.19%+(L28-500000000)*0.15%,IF(AND(L28>1000000000,L28<=5000000000),100000000*0.24%+400000000*0.19%+500000000*0.15%+(L28-1000000000)*0.12%,IF(L28>5000000000,100000000*0.24%+400000000*0.19%+500000000*0.15%+4000000000*0.12%+(L28-5000000000)*0.1%,"Bingung komputer"))))),2)} -> 382849.75 | E28: {=ROUND(IF(M28<=100000000,M28*0.24%,IF(AND(M28>100000000,M28<=500000000),100000000*0.24%+(M28-100000000)*0.19%,IF(AND(M28>500000000,M28<=1000000000),100000000*0.24%+400000000*0.19%+(M28-500000000)*0.15%,IF(AND(M28>1000000000,M28<=5000000000),100000000*0.24%+400000000*0.19%+500000000*0.15%+(M28-1000000000)*0.12%,IF(M28>5000000000,100000000*0.24%+400000000*0.19%+500000000*0.15%+4000000000*0.12%+(M28-5000000000)*0.1%,"Bingung komputer"))))),2)} -> 382676.21 | F28: {=ROUND(IF(N28<=100000000,N28*0.24%,IF(AND(N28>100000000,N28<=500000000),100000000*0.24%+(N28-100000000)*0.19%,IF(AND(N28>500000000,N28<=1000000000),100000000*0.24%+400000000*0.19%+(N28-500000000)*0.15%,IF(AND(N28>1000000000,N28<=5000000000),100000000*0.24%+400000000*0.19%+500000000*0.15%+(N28-1000000000)*0.12%,IF(N28>5000000000,100000000*0.24%+400000000*0.19%+500000000*0.15%+4000000000*0.12%+(N28-5000000000)*0.1%,"Bingung komputer"))))),2)} -> 382676.21 | K28: {="Jumlah Terkena Pajak "&MAX(K3:K26)&"% (B)"} -> Jumlah Terkena Pajak 11,00% (B) | L28: {=SUMIF($K3:$K26,">0",L3:L26)} -> 1.7518408e+08 | M28: {=SUMIF($K3:$K26,">0",M3:M26)} -> 1.7509274e+08 | N28: {=SUMIF($K3:$K26,">0",N3:N26)} -> 1.7509274e+08
K29: {="PPN (C) = "&MAX(K3:K26)&"% x B"} -> PPN (C) = 11,00% x B | L29: {=L28*MAX($K3:$K26)%} -> 19270249 | M29: {=M28*MAX($K3:$K26)%} -> 19260202 | N29: {=N28*MAX($K3:$K26)%} -> 19260202
K30: Jumlah Total (D) = (A) + ( C ) | L30: {=L27+L29} -> 1.9483718e+08 | M30: {=M27+M29} -> 1.9473562e+08 | N30: {=N27+N29} -> 1.9473562e+08
K31: Jumlah Total dibulatkan (E) | L31: {=ROUNDDOWN(L30,2)} -> 1.9483718e+08 | M31: {=ROUNDDOWN(M30,2)} -> 1.9473562e+08 | N31: {=ROUNDDOWN(N30,-3)} -> 194735000

Sheet 49013354
A1: No. | B1: Uraian Pekerjaan | D1: Kuantitas | G1: Satuan | H1: Harga Satuan | K1: PAJAK | L1: JUMLAH
D2: HPS | E2: Penawaran | F2: Negoisasi | H2: HPS | I2: Penawaran | J2: Negoisasi | L2: HPS | M2: Penawaran | N2: Negoisasi
B3: DIVISI 1. UMUM | L3: {=IF(D3>0,IF($D3<=0,0,D3*H3),"")} | M3: {=IF(E3>0,IF($D3<=0,0,ROUND(E3*I3,2)),"")} | N3: {=IF(F3>0,IF($D3<=0,0,ROUND(F3*J3,2)),"")}
A4: 1.2 | B4: Mobilisasi | D4: 1 | E4: {=D4} -> 1 | F4: {=D4} -> 1 | G4: LS | H4: 27510000 | I4: 27430000 | J4: 27430000 | K4: 11 | L4: {=IF(D4>0,IF($D4<=0,0,D4*H4),"")} -> 27510000 | M4: {=IF(E4>0,IF($D4<=0,0,ROUND(E4*I4,2)),"")} -> 27430000 | N4: {=IF(F4>0,IF($D4<=0,0,ROUND(F4*J4,2)),"")} -> 27430000
B5: DIVISI 3. PEKERJAAN TANAH | L5: {=IF(D5>0,IF($D5<=0,0,D5*H5),"")} | M5: {=IF(E5>0,IF($D5<=0,0,ROUND(E5*I5,2)),"")} | N5: {=IF(F5>0,IF($D5<=0,0,ROUND(F5*J5,2)),"")}
A6: 3.2.(1a) | B6: Timbunan Biasa dari sumber galian | D6: 675.75 | E6: {=D6} -> 675.75 | F6: {=D6} -> 675.75 | G6: M3 | H6: 207735.24 | I6: 207735.24 | J6: 207735.24 | K6: 11 | L6: {=IF(D6>0,IF($D6<=0,0,D6*H6),"")} -> 1.4037709e+08 | M6: {=IF(E6>0,IF($D6<=0,0,ROUND(E6*I6,2)),"")} -> 1.4037709e+08 | N6: {=IF(F6>0,IF($D6<=0,0,ROUND(F6*J6,2)),"")} -> 1.4037709e+08
A7: 3.3.(1) | B7: Penyiapan Badan Jalan | D7: 3975 | E7: {=D7} -> 3975 | F7: {=D7} -> 3975 | G7: M2 | H7: 1816.48 | I7: 1815.92 | J7: 1815.92 | K7: 11 | L7: {=IF(D7>0,IF($D7<=0,0,D7*H7),"")} -> 7220508 | M7: {=IF(E7>0,IF($D7<=0,0,ROUND(E7*I7,2)),"")} -> 7218282 | N7: {=IF(F7>0,IF($D7<=0,0,ROUND(F7*J7,2)),"")} -> 7218282
B8: Biaya BPJS Ketenaga Kerjaan | L8: {=IF(D8>0,IF($D8<=0,0,D8*H8),"")}
A9: 1 | B9: JKK/JKM | D9: 1 | E9: {=D9} -> 1 | F9: {=D9} -> 1 | G9: LS | H9: 382704 | I9: 382548 | J9: 382548 | K9: 0 | L9: {=IF(D9>0,IF($D9<=0,0,D9*H9),"")} -> 382704 | M9: {=IF(E9>0,IF($D9<=0,0,ROUND(E9*I9,2)),"")} -> 382548 | N9: {=IF(F9>0,IF($D9<=0,0,ROUND(F9*J9,2)),"")} -> 382548
K26: Jumlah Total (A) | L26: {=SUM(L1:L25)} -> 1.754903e+08 | M26: {=SUM(M1:M25)} -> 1.7540792e+08 | N26: {=SUM(N1:N25)} -> 1.7540792e+08
B27: HIT BPJS | D27: {=ROUND(IF(L27<=100000000,L27*0.24%,IF(AND(L27>100000000,L27<=500000000),100000000*0.24%+(L27-100000000)*0.19%,IF(AND(L27>500000000,L27<=1000000000),100000000*0.24%+400000000*0.19%+(L27-500000000)*0.15%,IF(AND(L27>1000000000,L27<=5000000000),100000000*0.24%+400000000*0.19%+500000000*0.15%+(L27-1000000000)*0.12%,IF(L27>5000000000,100000000*0.24%+400000000*0.19%+500000000*0.15%+4000000000*0.12%+(L27-5000000000)*0.1%,"Bingung komputer"))))),2)} -> 382704.43 | E27: {=ROUND(IF(M27<=100000000,M27*0.24%,IF(AND(M27>100000000,M27<=500000000),100000000*0.24%+(M27-100000000)*0.19%,IF(AND(M27>500000000,M27<=1000000000),100000000*0.24%+400000000*0.19%+(M27-500000000)*0.15%,IF(AND(M27>1000000000,M27<=5000000000),100000000*0.24%+400000000*0.19%+500000000*0.15%+(M27-1000000000)*0.12%,IF(M27>5000000000,100000000*0.24%+400000000*0.19%+500000000*0.15%+4000000000*0.12%+(M27-5000000000)*0.1%,"Bingung komputer"))))),2)} -> 382548.2 | F27: {=ROUND(IF(N27<=100000000,N27*0.24%,IF(AND(N27>100000000,N27<=500000000),100000000*0.24%+(N27-100000000)*0.19%,IF(AND(N27>500000000,N27<=1000000000),100000000*0.24%+400000000*0.19%+(N27-500000000)*0.15%,IF(AND(N27>1000000000,N27<=5000000000),100000000*0.24%+400000000*0.19%+500000000*0.15%+(N27-1000000000)*0.12%,IF(N27>5000000000,100000000*0.24%+400000000*0.19%+500000000*0.15%+4000000000*0.12%+(N27-5000000000)*0.1%,"Bingung komputer"))))),2)} -> 382548.2 | K27: {="Jumlah Terkena Pajak "&MAX(K3:K25)&"% (B)"} -> Jumlah Terkena Pajak 11,00% (B) | L27: {=SUMIF($K3:$K25,">0",L3:L25)} -> 1.751076e+08 | M27: {=SUMIF($K3:$K25,">0",M3:M25)} -> 1.7502537e+08 | N27: {=SUMIF($K3:$K25,">0",N3:N25)} -> 1.7502537e+08
K28: {="PPN (C) = "&MAX(K3:K25)&"% x B"} -> PPN (C) = 11,00% x B | L28: {=L27*MAX($K3:$K25)%} -> 19261836 | M28: {=M27*MAX($K3:$K25)%} -> 19252791 | N28: {=N27*MAX($K3:$K25)%} -> 19252791
K29: Jumlah Total (D) = (A) + ( C ) | L29: {=L26+L28} -> 1.9475214e+08 | M29: {=M26+M28} -> 1.9466071e+08 | N29: {=N26+N28} -> 1.9466071e+08
K30: Jumlah Total dibulatkan (E) | L30: {=ROUNDDOWN(L29,2)} -> 1.9475214e+08 | M30: {=ROUNDDOWN(M29,2)} -> 1.9466071e+08 | N30: {=ROUNDDOWN(N29,-3)} -> 194660000

Sheet 49013411
A1: No. | B1: Uraian Pekerjaan | D1: Kuantitas | G1: Satuan | H1: Harga Satuan | K1: PAJAK | L1: JUMLAH
D2: HPS | E2: Penawaran | F2: Negoisasi | H2: HPS | I2: Penawaran | J2: Negoisasi | L2: HPS | M2: Penawaran | N2: Negoisasi
B3: DIVISI 1. UMUM | L3: {=IF(D3>0,IF($D3<=0,0,D3*H3),"")} | M3: {=IF(E3>0,IF($D3<=0,0,ROUND(E3*I3,2)),"")} | N3: {=IF(F3>0,IF($D3<=0,0,ROUND(F3*J3,2)),"")}
A4: 1.2 | B4: Mobilisasi | D4: 1 | E4: {=D4} -> 1 | F4: {=D4} -> 1 | G4: LS | H4: 27062000 | I4: 27002000 | J4: 27002000 | K4: 11 | L4: {=IF(D4>0,IF($D4<=0,0,D4*H4),"")} -> 27062000 | M4: {=IF(E4>0,IF($D4<=0,0,ROUND(E4*I4,2)),"")} -> 27002000 | N4: {=IF(F4>0,IF($D4<=0,0,ROUND(F4*J4,2)),"")} -> 27002000
B5: DIVISI 3. PEKERJAAN TANAH | L5: {=IF(D5>0,IF($D5<=0,0,D5*H5),"")} | M5: {=IF(E5>0,IF($D5<=0,0,ROUND(E5*I5,2)),"")} | N5: {=IF(F5>0,IF($D5<=0,0,ROUND(F5*J5,2)),"")}
A6: 3.2.(1a) | B6: Timbunan Biasa dari sumber galian | D6: 537.63 | E6: {=D6} -> 537.63 | F6: {=D6} -> 537.63 | G6: M3 | H6: 266830.61 | I6: 266816.81 | J6: 266816.81 | K6: 11 | L6: {=IF(D6>0,IF($D6<=0,0,D6*H6),"")} -> 1.4345614e+08 | M6: {=IF(E6>0,IF($D6<=0,0,ROUND(E6*I6,2)),"")} -> 1.4344872e+08 | N6: {=IF(F6>0,IF($D6<=0,0,ROUND(F6*J6,2)),"")} -> 1.4344872e+08
A7: 3.3.(1) | B7: Penyiapan Badan Jalan | D7: 2530 | E7: {=D7} -> 2530 | F7: {=D7} -> 2530 | G7: M2 | H7: 1816.48 | I7: 1815.99 | J7: 1815.99 | K7: 11 | L7: {=IF(D7>0,IF($D7<=0,0,D7*H7),"")} -> 4595694.4 | M7: {=IF(E7>0,IF($D7<=0,0,ROUND(E7*I7,2)),"")} -> 4594454.7 | N7: {=IF(F7>0,IF($D7<=0,0,ROUND(F7*J7,2)),"")} -> 4594454.7
B8: Biaya BPJS Ketenaga Kerjaan | L8: {=IF(D8>0,IF($D8<=0,0,D8*H8),"")}
A9: 1 | B9: JKK/JKM | D9: 1 | E9: {=D9} -> 1 | F9: {=D9} -> 1 | G9: LS | H9: 382714 | I9: 382583 | J9: 382583 | K9: 0 | L9: {=IF(D9>0,IF($D9<=0,0,D9*H9),"")} -> 382714 | M9: {=IF(E9>0,IF($D9<=0,0,ROUND(E9*I9,2)),"")} -> 382583 | N9: {=IF(F9>0,IF($D9<=0,0,ROUND(F9*J9,2)),"")} -> 382583
K26: Jumlah Total (A) | L26: {=SUM(L1:L25)} -> 1.7549655e+08 | M26: {=SUM(M1:M25)} -> 1.7542776e+08 | N26: {=SUM(N1:N25)} -> 1.7542776e+08
B27: HIT BPJS | D27: {=ROUND(IF(L27<=100000000,L27*0.24%,IF(AND(L27>100000000,L27<=500000000),100000000*0.24%+(L27-100000000)*0.19%,IF(AND(L27>500000000,L27<=1000000000),100000000*0.24%+400000000*0.19%+(L27-500000000)*0.15%,IF(AND(L27>1000000000,L27<=5000000000),100000000*0.24%+400000000*0.19%+500000000*0.15%+(L27-1000000000)*0.12%,IF(L27>5000000000,100000000*0.24%+400000000*0.19%+500000000*0.15%+4000000000*0.12%+(L27-5000000000)*0.1%,"Bingung komputer"))))),2)} -> 382716.29 | E27: {=ROUND(IF(M27<=100000000,M27*0.24%,IF(AND(M27>100000000,M27<=500000000),100000000*0.24%+(M27-100000000)*0.19%,IF(AND(M27>500000000,M27<=1000000000),100000000*0.24%+400000000*0.19%+(M27-500000000)*0.15%,IF(AND(M27>1000000000,M27<=5000000000),100000000*0.24%+400000000*0.19%+500000000*0.15%+(M27-1000000000)*0.12%,IF(M27>5000000000,100000000*0.24%+400000000*0.19%+500000000*0.15%+4000000000*0.12%+(M27-5000000000)*0.1%,"Bingung komputer"))))),2)} -> 382585.83 | F27: {=ROUND(IF(N27<=100000000,N27*0.24%,IF(AND(N27>100000000,N27<=500000000),100000000*0.24%+(N27-100000000)*0.19%,IF(AND(N27>500000000,N27<=1000000000),100000000*0.24%+400000000*0.19%+(N27-500000000)*0.15%,IF(AND(N27>1000000000,N27<=5000000000),100000000*0.24%+400000000*0.19%+500000000*0.15%+(N27-1000000000)*0.12%,IF(N27>5000000000,100000000*0.24%+400000000*0.19%+500000000*0.15%+4000000000*0.12%+(N27-5000000000)*0.1%,"Bingung komputer"))))),2)} -> 382585.83 | K27: {="Jumlah Terkena Pajak "&MAX(K3:K25)&"% (B)"} -> Jumlah Terkena Pajak 11,00% (B) | L27: {=SUMIF($K3:$K25,">0",L3:L25)} -> 1.7511384e+08 | M27: {=SUMIF($K3:$K25,">0",M3:M25)} -> 1.7504518e+08 | N27: {=SUMIF($K3:$K25,">0",N3:N25)} -> 1.7504518e+08
K28: {="PPN (C) = "&MAX(K3:K25)&"% x B"} -> PPN (C) = 11,00% x B | L28: {=L27*MAX($K3:$K25)%} -> 19262522 | M28: {=M27*MAX($K3:$K25)%} -> 19254969 | N28: {=N27*MAX($K3:$K25)%} -> 19254969
K29: Jumlah Total (D) = (A) + ( C ) | L29: {=L26+L28} -> 1.9475907e+08 | M29: {=M26+M28} -> 1.9468273e+08 | N29: {=N26+N28} -> 1.9468273e+08
K30: Jumlah Total dibulatkan (E) | L30: {=ROUNDDOWN(L29,2)} -> 1.9475907e+08 | M30: {=ROUNDDOWN(M29,2)} -> 1.9468273e+08 | N30: {=ROUNDDOWN(N29,-3)} -> 194682000

Sheet 49013538
A1: No. | B1: Uraian Pekerjaan | D1: Kuantitas | G1: Satuan | H1: Harga Satuan | K1: PAJAK | L1: JUMLAH
D2: HPS | E2: Penawaran | F2: Negoisasi | H2: HPS | I2: Penawaran | J2: Negoisasi | L2: HPS | M2: Penawaran | N2: Negoisasi
B3: DIVISI 1. UMUM | L3: {=IF(D3>0,IF($D3<=0,0,D3*H3),"")} | M3: {=IF(E3>0,IF($D3<=0,0,ROUND(E3*I3,2)),"")} | N3: {=IF(F3>0,IF($D3<=0,0,ROUND(F3*J3,2)),"")}
A4: 1.2 | B4: Mobilisasi | D4: 1 | E4: {=D4} -> 1 | F4: {=D4} -> 1 | G4: LS | H4: 7760000 | I4: 7727500 | J4: 7727500 | K4: 11 | L4: {=IF(D4>0,IF($D4<=0,0,D4*H4),"")} -> 7760000 | M4: {=IF(E4>0,IF($D4<=0,0,ROUND(E4*I4,2)),"")} -> 7727500 | N4: {=IF(F4>0,IF($D4<=0,0,ROUND(F4*J4,2)),"")} -> 7727500
A5: 1.8.(1) | B5: Manajemen dan Keselamatan Lalu Lintas | D5: 1 | E5: {=D5} -> 1 | F5: {=D5} -> 1 | G5: LS | H5: 775000 | I5: 745000 | J5: 745000 | K5: 11 | L5: {=IF(D5>0,IF($D5<=0,0,D5*H5),"")} -> 775000 | M5: {=IF(E5>0,IF($D5<=0,0,ROUND(E5*I5,2)),"")} -> 745000 | N5: {=IF(F5>0,IF($D5<=0,0,ROUND(F5*J5,2)),"")} -> 745000
A6: 1.19 | B6: Keselamatan dan Kesehatan Kerja | D6: 1 | E6: {=D6} -> 1 | F6: {=D6} -> 1 | G6: LS | H6: 3503000 | I6: 3478000 | J6: 3478000 | K6: 11 | L6: {=IF(D6>0,IF($D6<=0,0,D6*H6),"")} -> 3503000 | M6: {=IF(E6>0,IF($D6<=0,0,ROUND(E6*I6,2)),"")} -> 3478000 | N6: {=IF(F6>0,IF($D6<=0,0,ROUND(F6*J6,2)),"")} -> 3478000
B7: DIVISI 3. PEKERJAAN TANAH DAN GEOSINTETIK | L7: {=IF(D7>0,IF($D7<=0,0,D7*H7),"")} | M7: {=IF(E7>0,IF($D7<=0,0,ROUND(E7*I7,2)),"")} | N7: {=IF(F7>0,IF($D7<=0,0,ROUND(F7*J7,2)),"")}
A8: 3.1.(4) | B8: Galian Struktur dengan kedalaman 0 - 2 meter | D8: 81.71 | E8: {=D8} -> 81.71 | F8: {=D8} -> 81.71 | G8: M3 | H8: 37558.16 | I8: 37554.14 | J8: 37554.14 | K8: 11 | L8: {=IF(D8>0,IF($D8<=0,0,D8*H8),"")} -> 3068877.3 | M8: {=IF(E8>0,IF($D8<=0,0,ROUND(E8*I8,2)),"")} -> 3068548.8 | N8: {=IF(F8>0,IF($D8<=0,0,ROUND(F8*J8,2)),"")} -> 3068548.8
B9: DIVISI 7. STRUKTUR | L9: {=IF(D9>0,IF($D9<=0,0,D9*H9),"")} | M9: {=IF(E9>0,IF($D9<=0,0,ROUND(E9*I9,2)),"")} | N9: {=IF(F9>0,IF($D9<=0,0,ROUND(F9*J9,2)),"")}
A10: 7.1 (5a) | B10: Beton struktur, fc’30 Mpa Bangunan Bawah (Abutmen) | D10: 31.28 | E10: {=D10} -> 31.28 | F10: {=D10} -> 31.28 | G10: M3 | H10: 1768272.6 | I10: 1768211.2 | J10: 1768211.2 | K10: 11 | L10: {=IF(D10>0,IF($D10<=0,0,D10*H10),"")} -> 55311567 | M10: {=IF(E10>0,IF($D10<=0,0,ROUND(E10*I10,2)),"")} -> 55309648 | N10: {=IF(F10>0,IF($D10<=0,0,ROUND(F10*J10,2)),"")} -> 55309648
A11: 7.1 (9) | B11: Beton Siklop, fc’15 Mpa | D11: 6.28 | E11: {=D11} -> 6.28 | F11: {=D11} -> 6.28 | G11: M3 | H11: 1002584.4 | I11: 1002584.4 | J11: 1002584.4 | K11: 11 | L11: {=IF(D11>0,IF($D11<=0,0,D11*H11),"")} -> 6296230.1 | M11: {=IF(E11>0,IF($D11<=0,0,ROUND(E11*I11,2)),"")} -> 6296230.1 | N11: {=IF(F11>0,IF($D11<=0,0,ROUND(F11*J11,2)),"")} -> 6296230.1
A12: 7.1 (10) | B12: Beton, fc’10 Mpa (Lantai Kerja) | D12: 2.5 | E12: {=D12} -> 2.5 | F12: {=D12} -> 2.5 | G12: M3 | H12: 1542982.1 | I12: 1542982.1 | J12: 1542982.1 | K12: 11 | L12: {=IF(D12>0,IF($D12<=0,0,D12*H12),"")} -> 3857455.2 | M12: {=IF(E12>0,IF($D12<=0,0,ROUND(E12*I12,2)),"")} -> 3857455.2 | N12: {=IF(F12>0,IF($D12<=0,0,ROUND(F12*J12,2)),"")} -> 3857455.2
A13: 7.3 (1) | B13: Baja Tulangan Polos-BjTP 280 (polos) | D13: 2411.07 | E13: {=D13} -> 2411.07 | F13: {=D13} -> 2411.07 | G13: kg | H13: 23089.13 | I13: 23080.5 | J13: 23080.5 | K13: 11 | L13: {=IF(D13>0,IF($D13<=0,0,D13*H13),"")} -> 55669509 | M13: {=IF(E13>0,IF($D13<=0,0,ROUND(E13*I13,2)),"")} -> 55648701 | N13: {=IF(F13>0,IF($D13<=0,0,ROUND(F13*J13,2)),"")} -> 55648701
A14: 7.9.(1) | B14: Pasangan Batu (Abutmen + Lenning) | D14: 49.79 | E14: {=D14} -> 49.79 | F14: {=D14} -> 49.79 | G14: M3 | H14: 805260.43 | I14: 805125.5 | J14: 805125.5 | K14: 11 | L14: {=IF(D14>0,IF($D14<=0,0,D14*H14),"")} -> 40093917 | M14: {=IF(E14>0,IF($D14<=0,0,ROUND(E14*I14,2)),"")} -> 40087199 | N14: {=IF(F14>0,IF($D14<=0,0,ROUND(F14*J14,2)),"")} -> 40087199
B15: DIVISI 9. PEKERJAAN HARIAN & PEKERJAAN LAIN-LAIN | L15: {=IF(D15>0,IF($D15<=0,0,D15*H15),"")} | M15: {=IF(E15>0,IF($D15<=0,0,ROUND(E15*I15,2)),"")} | N15: {=IF(F15>0,IF($D15<=0,0,ROUND(F15*J15,2)),"")}
A16: 9.1.(19) | B16: Pompa Air 70 - 100 mm | D16: 70 | E16: {=D16} -> 70 | F16: {=D16} -> 70 | G16: Jam | H16: 49007.67 | I16: 49007.67 | J16: 49007.67 | K16: 11 | L16: {=IF(D16>0,IF($D16<=0,0,D16*H16),"")} -> 3430536.9 | M16: {=IF(E16>0,IF($D16<=0,0,ROUND(E16*I16,2)),"")} -> 3430536.9 | N16: {=IF(F16>0,IF($D16<=0,0,ROUND(F16*J16,2)),"")} -> 3430536.9
B17: Biaya BPJS Ketenaga Kerjaan | L17: {=IF(D17>0,IF($D17<=0,0,D17*H17),"")}
A18: 1 | B18: JKK/JKM | D18: 1 | E18: {=D18} -> 1 | F18: {=D18} -> 1 | G18: LS | H18: 391555.22 | I18: 391332.42 | J18: 391332.42 | K18: 0 | L18: {=IF(D18>0,IF($D18<=0,0,D18*H18),"")} -> 391555.22 | M18: {=IF(E18>0,IF($D18<=0,0,ROUND(E18*I18,2)),"")} -> 391332.42 | N18: {=IF(F18>0,IF($D18<=0,0,ROUND(F18*J18,2)),"")} -> 391332.42
K35: Jumlah Total (A) | L35: {=SUM(L1:L34)} -> 1.8015765e+08 | M35: {=SUM(M1:M34)} -> 1.8004015e+08 | N35: {=SUM(N1:N34)} -> 1.8004015e+08
B36: HIT BPJS | D36: {=ROUND(IF(L36<=100000000,L36*0.24%,IF(AND(L36>100000000,L36<=500000000),100000000*0.24%+(L36-100000000)*0.19%,IF(AND(L36>500000000,L36<=1000000000),100000000*0.24%+400000000*0.19%+(L36-500000000)*0.15%,IF(AND(L36>1000000000,L36<=5000000000),100000000*0.24%+400000000*0.19%+500000000*0.15%+(L36-1000000000)*0.12%,IF(L36>5000000000,100000000*0.24%+400000000*0.19%+500000000*0.15%+4000000000*0.12%+(L36-5000000000)*0.1%,"Bingung komputer"))))),2)} -> 391555.57 | E36: {=ROUND(IF(M36<=100000000,M36*0.24%,IF(AND(M36>100000000,M36<=500000000),100000000*0.24%+(M36-100000000)*0.19%,IF(AND(M36>500000000,M36<=1000000000),100000000*0.24%+400000000*0.19%+(M36-500000000)*0.15%,IF(AND(M36>1000000000,M36<=5000000000),100000000*0.24%+400000000*0.19%+500000000*0.15%+(M36-1000000000)*0.12%,IF(M36>5000000000,100000000*0.24%+400000000*0.19%+500000000*0.15%+4000000000*0.12%+(M36-5000000000)*0.1%,"Bingung komputer"))))),2)} -> 391332.75 | F36: {=ROUND(IF(N36<=100000000,N36*0.24%,IF(AND(N36>100000000,N36<=500000000),100000000*0.24%+(N36-100000000)*0.19%,IF(AND(N36>500000000,N36<=1000000000),100000000*0.24%+400000000*0.19%+(N36-500000000)*0.15%,IF(AND(N36>1000000000,N36<=5000000000),100000000*0.24%+400000000*0.19%+500000000*0.15%+(N36-1000000000)*0.12%,IF(N36>5000000000,100000000*0.24%+400000000*0.19%+500000000*0.15%+4000000000*0.12%+(N36-5000000000)*0.1%,"Bingung komputer"))))),2)} -> 391332.75 | K36: {="Jumlah Terkena Pajak "&MAX(K3:K34)&"% (B)"} -> Jumlah Terkena Pajak 11,00% (B) | L36: {=SUMIF($K3:$K34,">0",L3:L34)} -> 1.7976609e+08 | M36: {=SUMIF($K3:$K34,">0",M3:M34)} -> 1.7964882e+08 | N36: {=SUMIF($K3:$K34,">0",N3:N34)} -> 1.7964882e+08
K37: {="PPN (C) = "&MAX(K3:K34)&"% x B"} -> PPN (C) = 11,00% x B | L37: {=L36*MAX($K3:$K34)%} -> 19774270 | M37: {=M36*MAX($K3:$K34)%} -> 19761370 | N37: {=N36*MAX($K3:$K34)%} -> 19761370
K38: Jumlah Total (D) = (A) + ( C ) | L38: {=L35+L37} -> 1.9993192e+08 | M38: {=M35+M37} -> 1.9980152e+08 | N38: {=N35+N37} -> 1.9980152e+08
K39: Jumlah Total dibulatkan (E) | L39: {=ROUNDDOWN(L38,2)} -> 1.9993192e+08 | M39: {=ROUNDDOWN(M38,2)} -> 1.9980152e+08 | N39: {=ROUNDDOWN(N38,-3)} -> 199801000

Sheet 49978186
A1: No. | B1: Uraian Pekerjaan | D1: Kuantitas | G1: Satuan | H1: Harga Satuan | K1: PAJAK | L1: JUMLAH
D2: HPS | E2: Penawaran | F2: Negoisasi | H2: HPS | I2: Penawaran | J2: Negoisasi | L2: HPS | M2: Penawaran | N2: Negoisasi
B3: Biaya perencanaan teknis | L3: {=IF(D3>0,IF($D3<=0,0,D3*H3),"")} | M3: {=IF(E3>0,IF($D3<=0,0,ROUND(E3*I3,2)),"")} | N3: {=IF(F3>0,IF($D3<=0,0,ROUND(F3*J3,2)),"")}
A4: 1 | B4: tahap konsepsi perancangan sebesar 10% | D4: 1 | E4: {=D4} -> 1 | F4: {=D4} -> 1 | G4: LS | H4: {=ROUNDDOWN((F$30*0.1)*100/111,-2)} -> 2247300 | I4: 2230000 | J4: 2230000 | K4: 11 | L4: {=IF(D4>0,IF($D4<=0,0,D4*H4),"")} -> 2247300 | M4: {=IF(E4>0,IF($D4<=0,0,ROUND(E4*I4,2)),"")} -> 2230000 | N4: {=IF(F4>0,IF($D4<=0,0,ROUND(F4*J4,2)),"")} -> 2230000
A5: 2 | B5: tahap pra rancangan sebesar 20% | D5: 1 | E5: {=D5} -> 1 | F5: {=D5} -> 1 | G5: LS | H5: {=ROUNDDOWN((F$30*0.2)*100/111,-2)} -> 4494700 | I5: 4490000 | J5: 4490000 | K5: 11 | L5: {=IF(D5>0,IF($D5<=0,0,D5*H5),"")} -> 4494700 | M5: {=IF(E5>0,IF($D5<=0,0,ROUND(E5*I5,2)),"")} -> 4490000 | N5: {=IF(F5>0,IF($D5<=0,0,ROUND(F5*J5,2)),"")} -> 4490000
A6: 3 | B6: tahap pengembangan rancangan sebesar 25% | D6: 1 | E6: {=D6} -> 1 | F6: {=D6} -> 1 | G6: LS | H6: {=ROUNDDOWN((F$30*0.25)*100/111,-2)} -> 5618400 | I6: 5600000 | J6: 5600000 | K6: 11 | L6: {=IF(D6>0,IF($D6<=0,0,D6*H6),"")} -> 5618400 | M6: {=IF(E6>0,IF($D6<=0,0,ROUND(E6*I6,2)),"")} -> 5600000 | N6: {=IF(F6>0,IF($D6<=0,0,ROUND(F6*J6,2)),"")} -> 5600000
A7: 5 | B7: tahap rancangan detail meliputi penyusunan rancangan gambar detail dan penyusunan Rencana Kerja dan Syarat (RKS), serta Rencana Anggaran Biaya (RAB) sebesar 25% | D7: 1 | E7: {=D7} -> 1 | F7: {=D7} -> 1 | G7: LS | H7: {=ROUNDDOWN((F$30*0.25)*100/111,-2)} -> 5618400 | I7: 5600000 | J7: 5600000 | K7: 11 | L7: {=IF(D7>0,IF($D7<=0,0,D7*H7),"")} -> 5618400 | M7: {=IF(E7>0,IF($D7<=0,0,ROUND(E7*I7,2)),"")} -> 5600000 | N7: {=IF(F7>0,IF($D7<=0,0,ROUND(F7*J7,2)),"")} -> 5600000
A8: 6 | B8: tahap pelelangan penyedia jasa pelaksanaan konstruksi sebesar 5% | D8: 1 | E8: {=D8} -> 1 | F8: {=D8} -> 1 | G8: LS | H8: {=ROUNDDOWN((F$30*0.05)*100/111,-2)} -> 1123600 | I8: 1125000 | J8: 1125000 | K8: 11 | L8: {=IF(D8>0,IF($D8<=0,0,D8*H8),"")} -> 1123600 | M8: {=IF(E8>0,IF($D8<=0,0,ROUND(E8*I8,2)),"")} -> 1125000 | N8: {=IF(F8>0,IF($D8<=0,0,ROUND(F8*J8,2)),"")} -> 1125000
A9: 7 | B9: tahap pengawasan berkala sebesar 15% | D9: 1 | E9: {=D9} -> 1 | F9: {=D9} -> 1 | G9: LS | H9: {=ROUNDDOWN((F$30*0.15)*100/111,-2)} -> 3371000 | I9: 3350000 | J9: 3350000 | K9: 11 | L9: {=IF(D9>0,IF($D9<=0,0,D9*H9),"")} -> 3371000 | M9: {=IF(E9>0,IF($D9<=0,0,ROUND(E9*I9,2)),"")} -> 3350000 | N9: {=IF(F9>0,IF($D9<=0,0,ROUND(F9*J9,2)),"")} -> 3350000
A10: 8 | B10: JKK/JKM | D10: 1 | E10: {=D10} -> 1 | F10: {=D10} -> 1 | G10: LS | H10: 53936.16 | I10: 53748 | J10: 53748 | K10: 0 | L10: {=IF(D10>0,IF($D10<=0,0,D10*H10),"")} -> 53936.16 | M10: {=IF(E10>0,IF($D10<=0,0,ROUND(E10*I10,2)),"")} -> 53748 | N10: {=IF(F10>0,IF($D10<=0,0,ROUND(F10*J10,2)),"")} -> 53748
K27: Jumlah Total (A) | L27: {=SUM(L1:L26)} -> 22527336 | M27: {=SUM(M1:M26)} -> 22448748 | N27: {=SUM(N1:N26)} -> 22448748
